Workbook

Sheet Summary
A1: Mellox AI: pricing and cost model v2 (OpenRouter model stack)
A2: Built from your model-migration spec and prices checked 2026-09-25. USD per month unless marked.
A4: How to use
A5: Blue = input, black = formula, green = link to another tab, yellow = the levers that move the answer. Swap a tier model on Inputs, a price on Vendor Prices or a plan limit on Plans and every tab updates. Video provider mode (split / openrouter / kie) and the Post for Me price are on Inputs.
A7: Plan | B7: Price | C7: Annual price | D7: Credits | E7: Video credits | F7: Pro messages | G7: Cost to serve (typical) | H7: Margin typical / worst
A8: Free | B8: =Plans!$C$6 -> 0 | C8: =Plans!$C$7 -> 0 | D8: =Plans!$C$10 -> 50 | E8: =Plans!$C$11 -> 0 | F8: =Plans!$C$12 -> 0 | G8: =Plans!$C$54 -> 0.91778372 | H8: =IF(Plans!$C$6=0,"n/a",TEXT(Plans!$C$61,"0%")&" / "&TEXT(Plans!$C$63,"0%")) -> n/a
A9: Starter | B9: =Plans!$D$6 -> 49 | C9: =Plans!$D$7 -> 40.8317 | D9: =Plans!$D$10 -> 2000 | E9: =Plans!$D$11 -> 4 | F9: =Plans!$D$12 -> 30 | G9: =Plans!$D$54 -> 11.928008 | H9: =IF(Plans!$D$6=0,"n/a",TEXT(Plans!$D$61,"0%")&" / "&TEXT(Plans!$D$63,"0%")) -> 67% / 43%
A10: Growth | B10: =Plans!$E$6 -> 149 | C10: =Plans!$E$7 -> 124.1617 | D10: =Plans!$E$10 -> 6000 | E10: =Plans!$E$11 -> 12 | F10: =Plans!$E$12 -> 150 | G10: =Plans!$E$54 -> 37.46599 | H10: =IF(Plans!$E$6=0,"n/a",TEXT(Plans!$E$61,"0%")&" / "&TEXT(Plans!$E$63,"0%")) -> 67% / 44%
A11: Agency | B11: =Plans!$F$6 -> 449 | C11: =Plans!$F$7 -> 374.1517 | D11: =Plans!$F$10 -> 18000 | E11: =Plans!$F$11 -> 40 | F11: =Plans!$F$12 -> 400 | G11: =Plans!$F$54 -> 115.94285 | H11: =IF(Plans!$F$6=0,"n/a",TEXT(Plans!$F$61,"0%")&" / "&TEXT(Plans!$F$63,"0%")) -> 67% / 45%
A12: Scale | B12: =Plans!$G$6 -> 1199 | C12: =Plans!$G$7 -> 999.1267 | D12: =Plans!$G$10 -> 50000 | E12: =Plans!$G$11 -> 100 | F12: =Plans!$G$12 -> 1200 | G12: =Plans!$G$54 -> 351.54697 | H12: =IF(Plans!$G$6=0,"n/a",TEXT(Plans!$G$61,"0%")&" / "&TEXT(Plans!$G$63,"0%")) -> 63% / 42%
A14: Key number | B14: Value
A15: Blended cost per Mellox credit | B15: =Inputs!$B$37 -> 0.0020341557
A16: Margin on credits at face value | B16: ='Credit Menu'!$K$41 -> 0.79658443
A17: Cost per video credit, OpenRouter | B17: ='Video Credits'!$K$20 -> 0.80883908
A18: Cost per video credit, KIE | B18: ='Video Credits'!$K$21 -> 0.39138333
A19: Chat message: Mellox Flash / Pro | B19: =TEXT('Unit Costs'!$AB$19,"$0.0000")&" / "&TEXT('Unit Costs'!$AB$20,"$0.0000") -> $0.0089 / $0.0482
A20: Brand DNA scan | B20: ='Unit Costs'!$AB$24 -> 0.23438541
A21: Premium article | B21: ='Unit Costs'!$AB$31 -> 0.19315557
A22: Image post | B22: ='Unit Costs'!$AB$28 -> 0.066162415
A23: One tracked prompt, 3 engines | B23: ='Unit Costs'!$AB$50 -> 0.015917312
A24: Standard 8s video on OpenRouter | B24: ='Video Credits'!F7 -> 0.844
A25: Fixed costs at launch | B25: ='Fixed Costs'!$C$25 -> 284.46667
A26: Break-even month (active scenario) | B26: =Projection!$B$55 -> 8
A27: MRR at month 12 / 24 | B27: =TEXT(Projection!$B$57,"$#,##0")&" / "&TEXT(Projection!$B$58,"$#,##0") -> $8,600 / $31,226
A29: Top risks (details on Risks & Fixes)
A30: [High] KIE carries Veo and Grok for now. If KIE goes away, Standard Veo 3.1 Fast 8s goes from $0.30 to $0.84 and Draft from $0.15 to $0.42.
A31: [High] Grok Imagine on OpenRouter costs $0.14/s (about $0.90 for 6s) versus $0.12 on KIE. If variation ever falls back to it, it costs more than a Standard video.
A32: [Medium] Social posting moved to Post for Me: $10 for 1,000 posts, unlimited accounts. Posts are now unlimited on every plan, Free included, and never use credits. A spam or bot account on Free could post thousands of times.
A33: [High] GEO probes: GPT-5.6 Luna and Gemini 3.8 Flash answer from memory (no web search), so they do not show what ChatGPT or Gemini users actually see. Google AI Overviews are not tracked at all, although the product promises them.
A34: [High] Premium routes now cost 2-9x more: Brand DNA $0.08 -> $0.24, articles $0.02 -> $0.20, Coach $0.10 -> $0.20, Market Brain $0.12 -> $0.25, GEO fix $0.10 -> $0.29.
A35: [Medium] Every free signup triggers an Opus Brand DNA scan + Brand Kit analysis: about $0.34 each, paid upfront even if the user never returns.

Sheet Inputs
A1: Global inputs, model tiers and levers
A2: Blue = typed input, green = from Vendor Prices, yellow = levers that move the answer most.
A4: Lever | B4: Value | C4: Notes / source
A5: USD to PKR rate | B5: ='Vendor Prices'!$G$58 -> 277.09
A6: Credit face value (USD per Mellox credit) | B6: 0.01 | C6: Same unit as the backlink ledger (100 credits per $)
A7: OpenRouter credit fee | B7: ='Vendor Prices'!$G$53 -> 0.055 | C7: Now charged on text, images and video
A8: Anthropic tokenizer factor (Opus family) | B8: 1.15 | C8: New Claude tokenizer counts 1.0-1.35x tokens
A9: PREMIUM tier model | B9: anthropic/claude-opus-5.5 | C9: task-models.ts PREMIUM
A10: WORKHORSE tier model | B10: google/gemini-3.8-flash | C10: task-models.ts WORKHORSE
A11: ECONOMY tier model | B11: google/gemini-3.1-flash-lite | C11: task-models.ts ECONOMY
A12: PREMIUM fallback | B12: google/gemini-3.8-flash | C12: Spec: falls back to WORKHORSE (effort high)
A13: WORKHORSE fallback | B13: openai/gpt-5.6-terra
A14: ECONOMY fallback | B14: openai/gpt-5.6-luna
A15: Share of calls answered by the fallback model | B15: 0.03 | C15: Watch in metering: answering model is now recorded
A16: Payment processor % (Paddle) | B16: ='Vendor Prices'!$G$54 -> 0.05
A17: Payment fixed fee per transaction | B17: ='Vendor Prices'!$G$55 -> 0.5
A18: Payout FX spread | B18: ='Vendor Prices'!$G$56 -> 0.02
A19: Pakistan IT export tax | B19: ='Vendor Prices'!$G$57 -> 0.0025
A20: Image re-roll factor | B20: 1.3 | C20: Users re-roll ~30% of images
A21: Typical use of included credits | B21: 0.5
A22: Typical use of included video credits | B22: 0.6 | C22: Video allowances get used more than general credits
A23: Typical use of included Mellox Pro messages | B23: 0.4
A24: Weeks per month | B24: 4.33
A25: Days per month | B25: 30
A26: Post for Me cost per published post | B26: =INDEX('Vendor Prices'!$G$5:$G$58,MATCH("postforme-starter",'Vendor Prices'!$A$5:$A$58,0))/INDEX('Vendor Prices'!$F$5:$F$58,MATCH("postforme-starter",'Vendor Prices'!$A$5:$A$58,0)) -> 0.01 | C26: Plan price / posts included. A post to 3 networks counts as 3 (assumed)
A27: Share of KIE renders that fall back to OpenRouter | B27: 0.05 | C27: KIE outage or refusal; fallback is billed at OpenRouter prices
A28: GEO crawl compute per page | B28: ='Vendor Prices'!$G$47 -> 0.0003
A29: Tavily $ per credit | B29: ='Vendor Prices'!$G$37 -> 0.008
A30: Video provider mode (split / openrouter / kie) | B30: split | C30: split = KIE for Veo (Standard, Draft) and Grok (Variation), OpenRouter for Premium, Cinematic, Long take and Studio
A31: Annual billing discount (2 months free) | B31: 0.1667 | C31: Pay 10 months, get 12
A32: Share of customers on annual | B32: 0.3
A33: Target margin: text and research credits | B33: 0.8
A34: Target margin: image credits | B34: 0.75
A35: Target margin: video credits (in packs) | B35: 0.6 | C35: Video market is price-competitive
A36: Backlink margin multiplier (recommended) | B36: 1.75
A37: Blended COGS per general credit | B37: ='Credit Menu'!$K$40 -> 0.0020341557 | C37: From Credit Menu mix
A38: Blended COGS per video credit | B38: ='Video Credits'!$K$19 -> 0.44614618 | C38: From Video Credits mix, active provider
A40: Reasoning tokens per call (estimate; calibrate from metering)
A41: Tier | B41: low | C41: medium | D41: high
A42: PREMIUM | B42: 800 | C42: 3000 | D42: 8000
...

Sheet Plans
A1: Plans v2: allowances and unit economics per customer (monthly, USD)
A2: Blue = plan design inputs. Typical = realistic usage. Worst = every allowance maxed at once. Video is its own allowance.
A4: Line | B4: Unit | C4: Free | D4: Starter | E4: Growth | F4: Agency | G4: Scale | H4: Notes
A5: PLAN DESIGN (inputs)
A6: List price, monthly billing | B6: $ / month | C6: 0 | D6: 49 | E6: 149 | F6: 449 | G6: 1199 | H6: v1 draft was $49 / $149 / $399 / $999
A7: Price on annual billing | B7: $ / month | C7: =C6*(1-Inputs!$B$31) -> 0 | D7: =D6*(1-Inputs!$B$31) -> 40.8317 | E7: =E6*(1-Inputs!$B$31) -> 124.1617 | F7: =F6*(1-Inputs!$B$31) -> 374.1517 | G7: =G6*(1-Inputs!$B$31) -> 999.1267
A8: Brands (client workspaces) | B8: count | C8: 1 | D8: 1 | E8: 3 | F8: 10 | G8: 30 | H8: Extra brand add-on $39
A9: Seats | B9: users | C9: 1 | D9: 2 | E9: 5 | F9: 9999 | G9: 9999 | H9: 9999 = unlimited
A10: Mellox credits (non-video AI work) | B10: credits / month | C10: 50 | D10: 2000 | E10: 6000 | F10: 18000 | G10: 50000 | H10: Free = 100 one-time, modeled as 50/month
A11: Video credits (1 VC = one 8s Standard video) | B11: VC / month | C11: 0 | D11: 4 | E11: 12 | F11: 40 | G11: 100 | H11: Separate from credits; packs for more
A12: Mellox Pro (Opus 5.5) chat messages | B12: messages / month | C12: 0 | D12: 30 | E12: 150 | F12: 400 | G12: 1200 | H12: Then 25 credits per message
A13: Mellox Flash chat fair use | B13: messages / month | C13: 30 | D13: 800 | E13: 2000 | F13: 5000 | G13: 12000 | H13: Then 2 credits per message
A14: Mellox Flash chat, typical | B14: messages / month | C14: 20 | D14: 250 | E14: 700 | F14: 2000 | G14: 6000
A15: Tracked AI-visibility prompts (weekly) | B15: prompts | C15: 5 | D15: 25 | E15: 100 | F15: 300 | G15: 1000 | H15: Pooled across brands
A16: Engine: Perplexity (Sonar) | B16: 1 = on | C16: 0 | D16: 1 | E16: 1 | F16: 1 | G16: 1
A17: Engine: 'ChatGPT' (GPT-5.6 Luna) | B17: 1 = on | C17: 1 | D17: 1 | E17: 1 | F17: 1 | G17: 1 | H17: No web search: see Risks
A18: Engine: Gemini (3.8 Flash) | B18: 1 = on | C18: 1 | D18: 1 | E18: 1 | F18: 1 | G18: 1 | H18: No web search: see Risks
A19: Engine: Google AI Overviews (DataForSEO) - add-on | B19: 1 = on | C19: 0 | D19: 0 | E19: 0 | F19: 0 | G19: 0 | H19: $15 add-on per 100 prompts
A20: Checks per prompt per engine | B20: per month | C20: =Inputs!$B$24 -> 4.33 | D20: =Inputs!$B$24 -> 4.33 | E20: =Inputs!$B$24 -> 4.33 | F20: =Inputs!$B$24 -> 4.33 | G20: =Inputs!$B$24 -> 4.33 | H20: Weekly; daily is an add-on
A21: Site scans | B21: per month | C21: 1 | D21: 4 | E21: 10 | F21: 30 | G21: 90
A22: Max pages per scan | B22: pages | C22: 25 | D22: 50 | E22: 150 | F22: 300 | G22: 500
A23: Competitors tracked | B23: count | C23: 0 | D23: 3 | E23: 10 | F23: 30 | G23: 90
A24: Update sweeps per competitor | B24: per month | C24: 0 | D24: 4.33 | E24: 8 | F24: 8 | G24: 8 | H24: About twice a week when active
A25: Market Brain: brands refreshed weekly | B25: count | C25: 0 | D25: 1 | E25: 3 | F25: 10 | G25: 30 | H25: Weekly for every brand on the plan
A26: Market Brain: brands refreshed daily | B26: count | C26: 0 | D26: 0 | E26: 0 | F26: 0 | G26: 0 | H26: Daily is a $29/brand add-on (Opus refresh = $0.25)
A27: Weekly auto Coach briefing (brands) | B27: count | C27: 0 | D27: 1 | E27: 1 | F27: 3 | G27: 10 | H27: The Monday email that brings people back
A28: Social posts a month, typical (each network counts) | B28: posts | C28: 30 | D28: 150 | E28: 450 | F28: 1500 | G28: 4500 | H28: Unlimited on every plan, never uses credits
A29: Social posts a month, fair-use cap (shown as unlimited) | B29: posts | C29: 100 | D29: 500 | E29: 1500 | F29: 5000 | G29: 15000 | H29: Fair-use cap (about 500 posts per brand); worst case uses it
A30: Proof Engine experiments open | B30: count | C30: 0 | D30: 1 | E30: 3 | F30: 15 | G30: 50
A31: Video renders at once | B31: count | C31: 0 | D31: 1 | E31: 2 | F31: 4 | G31: 8 | H31: UGC_MAX_CONCURRENT_RENDERS
A32: Publishing available | B32: 1 = yes | C32: 1 | D32: 1 | E32: 1 | F32: 1 | G32: 1 | H32: Free plan publishes too (unlimited posts)
A33: Background load vs a paid brand | B33: x | C33: 0.25 | D33: 1 | E33: 1 | F33: 1 | G33: 1 | H33: Free brands run no agents or Market Brain
A35: MONTHLY COST TO SERVE (formulas)
A36: Cost of 1 prompt across enabled engines | B36: $ | C36: =C16*'Unit Costs'!$AB$47+C17*'Unit Costs'!$AB$48+C18*'Unit Costs'!$AB$49+C19*'Unit Costs'!$AB$52 -> 0.0098510625 | D36: =D16*'Unit Costs'!$AB$47+D17*'Unit Costs'!$AB$48+D18*'Unit Costs'!$AB$49+D19*'Unit Costs'!$AB$52 -> 0.015917312 | E36: =E16*'Unit Costs'!$AB$47+E17*'Unit Costs'!$AB$48+E18*'Unit Costs'!$AB$49+E19*'Unit Costs'!$AB$52 -> 0.015917312 | F36: =F16*'Unit Costs'!$AB$47+F17*'Unit Costs'!$AB$48+F18*'Unit Costs'!$AB$49+F19*'Unit Costs'!$AB$52 -> 0.015917312 | G36: =G16*'Unit Costs'!$AB$47+G17*'Unit Costs'!$AB$48+G18*'Unit Costs'!$AB$49+G19*'Unit Costs'!$AB$52 -> 0.015917312
A37: AI-visibility prompt tracking | B37: $ | C37: =C15*C36*C20 -> 0.2132755 | D37: =D15*D36*D20 -> 1.7230491 | E37: =E15*E36*E20 -> 6.8921963 | F37: =F15*F36*F20 -> 20.676589 | G37: =G15*G36*G20 -> 68.921963
A38: Site scans | B38: $ | C38: =C21*(C22*Inputs!$B$28+5*Inputs!$B$29) -> 0.0475 | D38: =D21*(D22*Inputs!$B$28+5*Inputs!$B$29) -> 0.22 | E38: =E21*(E22*Inputs!$B$28+5*Inputs!$B$29) -> 0.85 | F38: =F21*(F22*Inputs!$B$28+5*Inputs!$B$29) -> 3.9 | G38: =G21*(G22*Inputs!$B$28+5*Inputs!$B$29) -> 17.1
A39: Competitor tracking | B39: $ | C39: =C23*C24*'Unit Costs'!$AB$43 -> 0 | D39: =D23*D24*'Unit Costs'!$AB$43 -> 0.23889867 | E39: =E23*E24*'Unit Costs'!$AB$43 -> 1.4712774 | F39: =F23*F24*'Unit Costs'!$AB$43 -> 4.4138322 | G39: =G23*G24*'Unit Costs'!$AB$43 -> 13.241497
A40: Market Brain | B40: $ | C40: =(C26*Inputs!$B$25+C25*Inputs!$B$24)*'Unit Costs'!$AB$40 -> 0 | D40: =(D26*Inputs!$B$25+D25*Inputs!$B$24)*'Unit Costs'!$AB$40 -> 1.0540924 | E40: =(E26*Inputs!$B$25+E25*Inputs!$B$24)*'Unit Costs'!$AB$40 -> 3.1622771 | F40: =(F26*Inputs!$B$25+F25*Inputs!$B$24)*'Unit Costs'!$AB$40 -> 10.540924 | G40: =(G26*Inputs!$B$25+G25*Inputs!$B$24)*'Unit Costs'!$AB$40 -> 31.622771
A41: Weekly Coach briefings | B41: $ | C41: =C27*Inputs!$B$24*'Unit Costs'!$AB$38 -> 0 | D41: =D27*Inputs!$B$24*'Unit Costs'!$AB$38 -> 0.84828714 | E41: =E27*Inputs!$B$24*'Unit Costs'!$AB$38 -> 0.84828714 | F41: =F27*Inputs!$B$24*'Unit Costs'!$AB$38 -> 2.5448614 | G41: =G27*Inputs!$B$24*'Unit Costs'!$AB$38 -> 8.4828714
A42: Publishing (typical posts) | B42: $ | C42: =C32*C28*Inputs!$B$26 -> 0.3 | D42: =D32*D28*Inputs!$B$26 -> 1.5 | E42: =E32*E28*Inputs!$B$26 -> 4.5 | F42: =F32*F28*Inputs!$B$26 -> 15 | G42: =G32*G28*Inputs!$B$26 -> 45
...

Sheet Feature Matrix
A1: What each plan includes, by module
A2: Included = no extra charge. Credits = paid from the monthly Mellox credits. VC = paid from Video Credits.
A4: Module | B4: Feature | C4: Free | D4: Starter | E4: Growth | F4: Agency | G4: Scale | H4: How it is metered
A5: Brand & onboarding | B5: Brand DNA scan (Opus 5.5) | C5: 1 brand | D5: 1 brand | E5: 3 brands | F5: 10 brands | G5: 30 brands | H5: First scan per brand included; re-scan 125 credits
B6: Brand Kit: visual + voice analysis | C6: - | D6: Yes | E6: Yes | F6: Yes | G6: Yes | H6: Included at onboarding; re-run 45 credits
B7: Assistant memory | C7: Yes | D7: Yes | E7: Yes | F7: Yes | G7: Yes | H7: Included
A8: Mellox Assistant | B8: Mellox Flash chat (Gemini 3.8 Flash) | C8: 30 messages | D8: 800 / month | E8: 2,000 | F8: 5,000 | G8: 12,000 | H8: Fair use, then 2 credits per message
B9: Mellox Pro chat (Claude Opus 5.5) | C9: - | D9: 30 / month | E9: 150 | F9: 400 pooled | G9: 1,200 pooled | H9: Then 25 credits per message
B10: Live web research in chat | C10: - | D10: Yes | E10: Yes | F10: Yes | G10: Yes | H10: Included
B11: File and image understanding | C11: 3 files | D11: Yes | E11: Yes | F11: Yes | G11: Yes | H11: 4 credits per file
A12: Studio | B12: Social posts, image posts, carousels, ads, scripts | C12: - | D12: Yes | E12: Yes | F12: Yes | G12: Yes | H12: Credits (7-30)
B13: Premium articles, GEO-grounded (Opus 5.5) | C13: - | D13: Yes | E13: Yes | F13: Yes | G13: Yes | H13: 100-140 credits
B14: Premium images and image edits | C14: - | D14: Yes | E14: Yes | F14: Yes | G14: Yes | H14: Credits (15-40)
B15: Campaign plans | C15: - | D15: - | E15: Yes | F15: Yes | G15: Yes | H15: 55 credits
B16: Content calendar and scheduling | C16: Yes | D16: Yes | E16: Yes | F16: Yes | G16: Yes | H16: Included
B17: Approval workflows | C17: - | D17: - | E17: Yes | F17: Yes | G17: Yes | H17: Included
A18: UGC video ads | B18: UGC concepts, hooks and scripts | C18: - | D18: Yes | E18: Yes | F18: Yes | G18: Yes | H18: 25 credits
B19: Video credits per month | C19: - | D19: 4 | E19: 12 | F19: 40 pooled | G19: 100 pooled | H19: Video Packs for more; never paid with general credits
B20: Draft and Standard video, 720p | C20: - | D20: Yes | E20: Yes | F20: Yes | G20: Yes | H20: 0.5 / 1 VC
B21: 1080p, Premium and Long-take video | C21: - | D21: - | E21: Yes | F21: Yes | G21: Yes | H21: 0.75-2 VC
B22: Cinematic multi-shot video | C22: - | D22: - | E22: - | F22: Yes | G22: Yes | H22: 2 VC
B23: Renders at the same time | C23: - | D23: 1 | E23: 2 | F23: 4 | G23: 8 | H23: Concurrency limit
A24: AI Visibility | B24: Tracked prompts, checked weekly | C24: 5 | D24: 25 | E24: 100 | F24: 300 pooled | G24: 1,000 pooled | H24: +100 prompts $39; daily tracking add-on
B25: Answer engines | C25: ChatGPT, Gemini | D25: + Perplexity | E25: 3 engines | F25: 3 engines | G25: 3 engines | H25: Google AI Overviews add-on $15 / 100 prompts
B26: Site scans per month (max pages) | C26: 1 (25) | D26: 4 (50) | E26: 10 (150) | F26: 30 (300) | G26: 90 (500) | H26: Extra scan 35 credits per 100 pages
B27: Findings, scores, readiness dashboard | C27: Yes | D27: Yes | E27: Yes | F27: Yes | G27: Yes | H27: Included
B28: GEO fix proposals | C28: View findings | D28: Yes | E28: Yes | F28: Yes | G28: Yes | H28: 150 credits per finding
B29: CMS fixes (WordPress, Webflow) | C29: - | D29: - | E29: Yes | F29: Yes | G29: Yes | H29: 55 credits
B30: GitHub PR fixes + GEO Engineer agent | C30: - | D30: - | E30: - | F30: Yes | G30: Yes | H30: 800 credits per run
B31: Verification rescans after fixes | C31: - | D31: Yes | E31: Yes | F31: Yes | G31: Yes | H31: Included
B32: Proof Engine experiments open | C32: - | D32: 1 | E32: 3 | F32: 15 | G32: 50 | H32: 70 credits each
A33: Intelligence | B33: Weekly Marketing Coach briefing (auto) | C33: - | D33: 1 brand | E33: 1 brand | F33: 3 brands | G33: 10 brands | H33: On-demand briefing 100 credits
B34: Market Brain market updates | C34: - | D34: Weekly, 1 brand | E34: Weekly, 3 | F34: Weekly, 10 | G34: Weekly, 30 | H34: Daily add-on $29 per brand
B35: Competitors tracked | C35: - | D35: 3 | E35: 10 | F35: 30 | G35: 90 | H35: Discovery 25 credits
B36: Competitor intelligence reports | C36: - | D36: Yes | E36: Yes | F36: Yes | G36: Yes | H36: 30 credits
B37: GA4 and Search Console insights | C37: - | D37: Yes | E37: Yes | F37: Yes | G37: Yes | H37: Included
A38: Distribution | B38: Social publishing (all networks, unlimited accounts) | C38: Unlimited posts | D38: Unlimited | E38: Unlimited | F38: Unlimited | G38: Unlimited | H38: Never uses credits; fair use
B39: WordPress and Webflow publishing | C39: - | D39: Yes | E39: Yes | F39: Yes | G39: Yes | H39: Included
B40: Backlink marketplace | C40: - | D40: - | E40: Yes | F40: Yes | G40: Yes | H40: Provider price x 1.75
A41: Team & agency | B41: Seats | C41: 1 | D41: 2 | E41: 5 | F41: Unlimited | G41: Unlimited | H41: +$15 per seat
...

Sheet Credit Menu
A1: Mellox Credits: price list for non-video AI work (1 credit = $0.01)
A2: Video is NOT paid with these credits: it has its own Video Credits (next tab). Blue = credits charged. Status flags anything below target margin.
A4: Action (what the customer sees) | B4: Unit | C4: COGS ($) | D4: Credits | E4: List price ($) | F4: Margin | G4: Target | H4: Status | I4: Credits for target | J4: Expected share of use | K4: COGS per credit ($) | L4: Unit cost ID | M4: Change vs v1 (credits)
A5: Social post set (up to 3 platforms) | B5: per job | C5: ='Unit Costs'!$AB$27 -> 0.022781479 | D5: 12 | E5: =D5*Inputs!$B$6 -> 0.12 | F5: =IF(E5=0,"included",1-C5/E5) -> 0.81015434 | G5: =Inputs!$B$33 -> 0.8 | H5: =IF(D5=0,"Included (fair use)",IF(F5>=G5-0.025,"OK","RAISE")) -> OK | I5: =ROUNDUP(C5/(1-G5)/Inputs!$B$6,0) -> 12 | J5: 0.12 | K5: =IF(D5=0,0,C5/D5) -> 0.0018984566 | L5: post_set | M5: 8
A6: Image post (copy + image) | B6: per job | C6: ='Unit Costs'!$AB$28 -> 0.066162415 | D6: 30 | E6: =D6*Inputs!$B$6 -> 0.3 | F6: =IF(E6=0,"included",1-C6/E6) -> 0.77945862 | G6: =Inputs!$B$34 -> 0.75 | H6: =IF(D6=0,"Included (fair use)",IF(F6>=G6-0.025,"OK","RAISE")) -> OK | I6: =ROUNDUP(C6/(1-G6)/Inputs!$B$6,0) -> 27 | J6: 0.16 | K6: =IF(D6=0,0,C6/D6) -> 0.0022054138 | L6: image_post | M6: 20
A7: Carousel | B7: per job | C7: ='Unit Costs'!$AB$29 -> 0.059909562 | D7: 30 | E7: =D7*Inputs!$B$6 -> 0.3 | F7: =IF(E7=0,"included",1-C7/E7) -> 0.80030146 | G7: =Inputs!$B$34 -> 0.75 | H7: =IF(D7=0,"Included (fair use)",IF(F7>=G7-0.025,"OK","RAISE")) -> OK | I7: =ROUNDUP(C7/(1-G7)/Inputs!$B$6,0) -> 24 | J7: 0.04 | K7: =IF(D7=0,0,C7/D7) -> 0.0019969854 | L7: carousel | M7: 20
A8: Ad set (copy + image) | B8: per job | C8: ='Unit Costs'!$AB$30 -> 0.058053923 | D8: 30 | E8: =D8*Inputs!$B$6 -> 0.3 | F8: =IF(E8=0,"included",1-C8/E8) -> 0.80648692 | G8: =Inputs!$B$34 -> 0.75 | H8: =IF(D8=0,"Included (fair use)",IF(F8>=G8-0.025,"OK","RAISE")) -> OK | I8: =ROUNDUP(C8/(1-G8)/Inputs!$B$6,0) -> 24 | J8: 0.05 | K8: =IF(D8=0,0,C8/D8) -> 0.0019351308 | L8: ad_set | M8: 20
A9: Premium article (~1,200 words, GEO-grounded) | B9: per article | C9: ='Unit Costs'!$AB$31 -> 0.19315557 | D9: 100 | E9: =D9*Inputs!$B$6 -> 1 | F9: =IF(E9=0,"included",1-C9/E9) -> 0.80684443 | G9: =Inputs!$B$33 -> 0.8 | H9: =IF(D9=0,"Included (fair use)",IF(F9>=G9-0.025,"OK","RAISE")) -> OK | I9: =ROUNDUP(C9/(1-G9)/Inputs!$B$6,0) -> 97 | J9: 0.06 | K9: =IF(D9=0,0,C9/D9) -> 0.0019315557 | L9: article | M9: 15
A10: Long-form article (~2,500 words) | B10: per article | C10: ='Unit Costs'!$AB$32 -> 0.27341737 | D10: 140 | E10: =D10*Inputs!$B$6 -> 1.4 | F10: =IF(E10=0,"included",1-C10/E10) -> 0.80470188 | G10: =Inputs!$B$33 -> 0.8 | H10: =IF(D10=0,"Included (fair use)",IF(F10>=G10-0.025,"OK","RAISE")) -> OK | I10: =ROUNDUP(C10/(1-G10)/Inputs!$B$6,0) -> 137 | J10: 0.02 | K10: =IF(D10=0,0,C10/D10) -> 0.0019529812 | L10: article_long | M10: 25
A11: Standard article (proposed WORKHORSE tier) | B11: per article | C11: ='Unit Costs'!$AB$33 -> 0.031421909 | D11: 20 | E11: =D11*Inputs!$B$6 -> 0.2 | F11: =IF(E11=0,"included",1-C11/E11) -> 0.84289045 | G11: =Inputs!$B$33 -> 0.8 | H11: =IF(D11=0,"Included (fair use)",IF(F11>=G11-0.025,"OK","RAISE")) -> OK | I11: =ROUNDUP(C11/(1-G11)/Inputs!$B$6,0) -> 16 | J11: 0 | K11: =IF(D11=0,0,C11/D11) -> 0.0015710955 | L11: article_std | M11: new
A12: Video script | B12: per script | C12: ='Unit Costs'!$AB$34 -> 0.020813277 | D12: 10 | E12: =D12*Inputs!$B$6 -> 0.1 | F12: =IF(E12=0,"included",1-C12/E12) -> 0.79186723 | G12: =Inputs!$B$33 -> 0.8 | H12: =IF(D12=0,"Included (fair use)",IF(F12>=G12-0.025,"OK","RAISE")) -> OK | I12: =ROUNDUP(C12/(1-G12)/Inputs!$B$6,0) -> 11 | J12: 0.02 | K12: =IF(D12=0,0,C12/D12) -> 0.0020813277 | L12: script | M12: 6
A13: Content ideas batch | B13: per batch | C13: ='Unit Costs'!$AB$35 -> 0.014282062 | D13: 7 | E13: =D13*Inputs!$B$6 -> 0.07 | F13: =IF(E13=0,"included",1-C13/E13) -> 0.79597054 | G13: =Inputs!$B$33 -> 0.8 | H13: =IF(D13=0,"Included (fair use)",IF(F13>=G13-0.025,"OK","RAISE")) -> OK | I13: =ROUNDUP(C13/(1-G13)/Inputs!$B$6,0) -> 8 | J13: 0.02 | K13: =IF(D13=0,0,C13/D13) -> 0.0020402946 | L13: ideas | M13: new
A14: Multi-platform variants (5 platforms) | B14: per job | C14: ='Unit Costs'!$AB$36 -> 0.018933821 | D14: 10 | E14: =D14*Inputs!$B$6 -> 0.1 | F14: =IF(E14=0,"included",1-C14/E14) -> 0.81066179 | G14: =Inputs!$B$33 -> 0.8 | H14: =IF(D14=0,"Included (fair use)",IF(F14>=G14-0.025,"OK","RAISE")) -> OK | I14: =ROUNDUP(C14/(1-G14)/Inputs!$B$6,0) -> 10 | J14: 0.02 | K14: =IF(D14=0,0,C14/D14) -> 0.0018933821 | L14: social_multi | M14: new
A15: Standard image | B15: per image | C15: ='Unit Costs'!$AB$16 -> 0.036783699 | D15: 15 | E15: =D15*Inputs!$B$6 -> 0.15 | F15: =IF(E15=0,"included",1-C15/E15) -> 0.75477534 | G15: =Inputs!$B$34 -> 0.75 | H15: =IF(D15=0,"Included (fair use)",IF(F15>=G15-0.025,"OK","RAISE")) -> OK | I15: =ROUNDUP(C15/(1-G15)/Inputs!$B$6,0) -> 15 | J15: 0.05 | K15: =IF(D15=0,0,C15/D15) -> 0.0024522466 | L15: img_std | M15: 12
A16: Premium image | B16: per image | C16: ='Unit Costs'!$AB$17 -> 0.086157699 | D16: 40 | E16: =D16*Inputs!$B$6 -> 0.4 | F16: =IF(E16=0,"included",1-C16/E16) -> 0.78460575 | G16: =Inputs!$B$34 -> 0.75 | H16: =IF(D16=0,"Included (fair use)",IF(F16>=G16-0.025,"OK","RAISE")) -> OK | I16: =ROUNDUP(C16/(1-G16)/Inputs!$B$6,0) -> 35 | J16: 0.03 | K16: =IF(D16=0,0,C16/D16) -> 0.0021539425 | L16: img_prem | M16: 30
A17: Image edit (up to 2 references) | B17: per edit | C17: ='Unit Costs'!$AB$18 -> 0.050239153 | D17: 20 | E17: =D17*Inputs!$B$6 -> 0.2 | F17: =IF(E17=0,"included",1-C17/E17) -> 0.74880424 | G17: =Inputs!$B$34 -> 0.75 | H17: =IF(D17=0,"Included (fair use)",IF(F17>=G17-0.025,"OK","RAISE")) -> OK | I17: =ROUNDUP(C17/(1-G17)/Inputs!$B$6,0) -> 21 | J17: 0.02 | K17: =IF(D17=0,0,C17/D17) -> 0.0025119576 | L17: img_edit | M17: new
A18: Campaign plan | B18: per plan | C18: ='Unit Costs'!$AB$37 -> 0.10645082 | D18: 55 | E18: =D18*Inputs!$B$6 -> 0.55 | F18: =IF(E18=0,"included",1-C18/E18) -> 0.80645306 | G18: =Inputs!$B$33 -> 0.8 | H18: =IF(D18=0,"Included (fair use)",IF(F18>=G18-0.025,"OK","RAISE")) -> OK | I18: =ROUNDUP(C18/(1-G18)/Inputs!$B$6,0) -> 54 | J18: 0.02 | K18: =IF(D18=0,0,C18/D18) -> 0.0019354694 | L18: campaign | M18: 20
A19: Brand DNA re-scan (first scan per brand free) | B19: per scan | C19: ='Unit Costs'!$AB$24 -> 0.23438541 | D19: 125 | E19: =D19*Inputs!$B$6 -> 1.25 | F19: =IF(E19=0,"included",1-C19/E19) -> 0.81249167 | G19: =Inputs!$B$33 -> 0.8 | H19: =IF(D19=0,"Included (fair use)",IF(F19>=G19-0.025,"OK","RAISE")) -> OK | I19: =ROUNDUP(C19/(1-G19)/Inputs!$B$6,0) -> 118 | J19: 0.01 | K19: =IF(D19=0,0,C19/D19) -> 0.0018750833 | L19: brand_dna | M19: 40
A20: Brand voice re-analysis | B20: per run | C20: ='Unit Costs'!$AB$25 -> 0.082795081 | D20: 45 | E20: =D20*Inputs!$B$6 -> 0.45 | F20: =IF(E20=0,"included",1-C20/E20) -> 0.81601093 | G20: =Inputs!$B$33 -> 0.8 | H20: =IF(D20=0,"Included (fair use)",IF(F20>=G20-0.025,"OK","RAISE")) -> OK | I20: =ROUNDUP(C20/(1-G20)/Inputs!$B$6,0) -> 42 | J20: 0.005 | K20: =IF(D20=0,0,C20/D20) -> 0.0018398907 | L20: brand_writing | M20: new
A21: File / image extraction | B21: per file | C21: ='Unit Costs'!$AB$23 -> 0.0077876935 | D21: 4 | E21: =D21*Inputs!$B$6 -> 0.04 | F21: =IF(E21=0,"included",1-C21/E21) -> 0.80530766 | G21: =Inputs!$B$33 -> 0.8 | H21: =IF(D21=0,"Included (fair use)",IF(F21>=G21-0.025,"OK","RAISE")) -> OK | I21: =ROUNDUP(C21/(1-G21)/Inputs!$B$6,0) -> 4 | J21: 0.01 | K21: =IF(D21=0,0,C21/D21) -> 0.0019469234 | L21: file_extract | M21: 10
A22: Marketing Coach briefing (on demand) | B22: per briefing | C22: ='Unit Costs'!$AB$38 -> 0.19590927 | D22: 100 | E22: =D22*Inputs!$B$6 -> 1 | F22: =IF(E22=0,"included",1-C22/E22) -> 0.80409073 | G22: =Inputs!$B$33 -> 0.8 | H22: =IF(D22=0,"Included (fair use)",IF(F22>=G22-0.025,"OK","RAISE")) -> OK | I22: =ROUNDUP(C22/(1-G22)/Inputs!$B$6,0) -> 98 | J22: 0.04 | K22: =IF(D22=0,0,C22/D22) -> 0.0019590927 | L22: coach | M22: 50
A23: Deep strategy (Coach, high effort) | B23: per run | C23: ='Unit Costs'!$AB$39 -> 0.37474665 | D23: 200 | E23: =D23*Inputs!$B$6 -> 2 | F23: =IF(E23=0,"included",1-C23/E23) -> 0.81262668 | G23: =Inputs!$B$33 -> 0.8 | H23: =IF(D23=0,"Included (fair use)",IF(F23>=G23-0.025,"OK","RAISE")) -> OK | I23: =ROUNDUP(C23/(1-G23)/Inputs!$B$6,0) -> 188 | J23: 0.02 | K23: =IF(D23=0,0,C23/D23) -> 0.0018737332 | L23: coach_deep | M23: 150
A24: Market Brain manual refresh | B24: per refresh | C24: ='Unit Costs'!$AB$40 -> 0.24343934 | D24: 125 | E24: =D24*Inputs!$B$6 -> 1.25 | F24: =IF(E24=0,"included",1-C24/E24) -> 0.80524853 | G24: =Inputs!$B$33 -> 0.8 | H24: =IF(D24=0,"Included (fair use)",IF(F24>=G24-0.025,"OK","RAISE")) -> OK | I24: =ROUNDUP(C24/(1-G24)/Inputs!$B$6,0) -> 122 | J24: 0.02 | K24: =IF(D24=0,0,C24/D24) -> 0.0019475147 | L24: market_brain | M24: 60
A25: Competitor discovery | B25: per run | C25: ='Unit Costs'!$AB$41 -> 0.051391164 | D25: 25 | E25: =D25*Inputs!$B$6 -> 0.25 | F25: =IF(E25=0,"included",1-C25/E25) -> 0.79443535 | G25: =Inputs!$B$33 -> 0.8 | H25: =IF(D25=0,"Included (fair use)",IF(F25>=G25-0.025,"OK","RAISE")) -> OK | I25: =ROUNDUP(C25/(1-G25)/Inputs!$B$6,0) -> 26 | J25: 0.01 | K25: =IF(D25=0,0,C25/D25) -> 0.0020556465 | L25: comp_disc | M25: 40
A26: Competitor profile | B26: per competitor | C26: ='Unit Costs'!$AB$42 -> 0.030697469 | D26: 15 | E26: =D26*Inputs!$B$6 -> 0.15 | F26: =IF(E26=0,"included",1-C26/E26) -> 0.79535021 | G26: =Inputs!$B$33 -> 0.8 | H26: =IF(D26=0,"Included (fair use)",IF(F26>=G26-0.025,"OK","RAISE")) -> OK | I26: =ROUNDUP(C26/(1-G26)/Inputs!$B$6,0) -> 16 | J26: 0.01 | K26: =IF(D26=0,0,C26/D26) -> 0.0020464979 | L26: comp_profile | M26: 25
A27: Competitor intelligence report | B27: per report | C27: ='Unit Costs'!$AB$44 -> 0.056768828 | D27: 30 | E27: =D27*Inputs!$B$6 -> 0.3 | F27: =IF(E27=0,"included",1-C27/E27) -> 0.81077058 | G27: =Inputs!$B$33 -> 0.8 | H27: =IF(D27=0,"Included (fair use)",IF(F27>=G27-0.025,"OK","RAISE")) -> OK | I27: =ROUNDUP(C27/(1-G27)/Inputs!$B$6,0) -> 29 | J27: 0.01 | K27: =IF(D27=0,0,C27/D27) -> 0.0018922942 | L27: comp_intel | M27: 50
A28: Analytics insight refresh (on demand) | B28: per refresh | C28: ='Unit Costs'!$AB$45 -> 0.01680615 | D28: 8 | E28: =D28*Inputs!$B$6 -> 0.08 | F28: =IF(E28=0,"included",1-C28/E28) -> 0.78992312 | G28: =Inputs!$B$33 -> 0.8 | H28: =IF(D28=0,"Included (fair use)",IF(F28>=G28-0.025,"OK","RAISE")) -> OK | I28: =ROUNDUP(C28/(1-G28)/Inputs!$B$6,0) -> 9 | J28: 0.01 | K28: =IF(D28=0,0,C28/D28) -> 0.0021007687 | L28: insights | M28: new
A29: Extra site scan | B29: per 100 pages | C29: ='Unit Costs'!$AB$46 -> 0.07 | D29: 35 | E29: =D29*Inputs!$B$6 -> 0.35 | F29: =IF(E29=0,"included",1-C29/E29) -> 0.8 | G29: =Inputs!$B$33 -> 0.8 | H29: =IF(D29=0,"Included (fair use)",IF(F29>=G29-0.025,"OK","RAISE")) -> OK | I29: =ROUNDUP(C29/(1-G29)/Inputs!$B$6,0) -> 35 | J29: 0.01 | K29: =IF(D29=0,0,C29/D29) -> 0.002 | L29: site_scan | M29: 35
A30: Extra prompt check (3 engines) | B30: per prompt | C30: ='Unit Costs'!$AB$50 -> 0.015917312 | D30: 8 | E30: =D30*Inputs!$B$6 -> 0.08 | F30: =IF(E30=0,"included",1-C30/E30) -> 0.80103359 | G30: =Inputs!$B$33 -> 0.8 | H30: =IF(D30=0,"Included (fair use)",IF(F30>=G30-0.025,"OK","RAISE")) -> OK | I30: =ROUNDUP(C30/(1-G30)/Inputs!$B$6,0) -> 8 | J30: 0.02 | K30: =IF(D30=0,0,C30/D30) -> 0.0019896641 | L30: probe_set | M30: new
A31: GEO fix proposal | B31: per finding | C31: ='Unit Costs'!$AB$53 -> 0.28623442 | D31: 150 | E31: =D31*Inputs!$B$6 -> 1.5 | F31: =IF(E31=0,"included",1-C31/E31) -> 0.80917705 | G31: =Inputs!$B$33 -> 0.8 | H31: =IF(D31=0,"Included (fair use)",IF(F31>=G31-0.025,"OK","RAISE")) -> OK | I31: =ROUNDUP(C31/(1-G31)/Inputs!$B$6,0) -> 144 | J31: 0.06 | K31: =IF(D31=0,0,C31/D31) -> 0.0019082295 | L31: geo_fix | M31: 50
A32: GEO CMS fix (WordPress / Webflow) | B32: per fix | C32: ='Unit Costs'!$AB$54 -> 0.10706053 | D32: 55 | E32: =D32*Inputs!$B$6 -> 0.55 | F32: =IF(E32=0,"included",1-C32/E32) -> 0.80534449 | G32: =Inputs!$B$33 -> 0.8 | H32: =IF(D32=0,"Included (fair use)",IF(F32>=G32-0.025,"OK","RAISE")) -> OK | I32: =ROUNDUP(C32/(1-G32)/Inputs!$B$6,0) -> 54 | J32: 0.03 | K32: =IF(D32=0,0,C32/D32) -> 0.0019465551 | L32: geo_cms | M32: 60
A33: GEO Engineer agent run (GitHub PR) | B33: per run | C33: ='Unit Costs'!$AB$55 -> 1.6 | D33: 800 | E33: =D33*Inputs!$B$6 -> 8 | F33: =IF(E33=0,"included",1-C33/E33) -> 0.8 | G33: =Inputs!$B$33 -> 0.8 | H33: =IF(D33=0,"Included (fair use)",IF(F33>=G33-0.025,"OK","RAISE")) -> OK | I33: =ROUNDUP(C33/(1-G33)/Inputs!$B$6,0) -> 800 | J33: 0.03 | K33: =IF(D33=0,0,C33/D33) -> 0.002 | L33: geo_agent | M33: 400
A34: Proof Engine experiment | B34: per experiment | C34: ='Unit Costs'!$AB$56 -> 0.14362084 | D34: 70 | E34: =D34*Inputs!$B$6 -> 0.7 | F34: =IF(E34=0,"included",1-C34/E34) -> 0.79482737 | G34: =Inputs!$B$33 -> 0.8 | H34: =IF(D34=0,"Included (fair use)",IF(F34>=G34-0.025,"OK","RAISE")) -> OK | I34: =ROUNDUP(C34/(1-G34)/Inputs!$B$6,0) -> 72 | J34: 0.01 | K34: =IF(D34=0,0,C34/D34) -> 0.0020517263 | L34: experiment | M34: 80
A35: UGC concept pack (scripts and hooks) | B35: per product | C35: ='Unit Costs'!$AB$57 -> 0.051274582 | D35: 25 | E35: =D35*Inputs!$B$6 -> 0.25 | F35: =IF(E35=0,"included",1-C35/E35) -> 0.79490167 | G35: =Inputs!$B$33 -> 0.8 | H35: =IF(D35=0,"Included (fair use)",IF(F35>=G35-0.025,"OK","RAISE")) -> OK | I35: =ROUNDUP(C35/(1-G35)/Inputs!$B$6,0) -> 26 | J35: 0.03 | K35: =IF(D35=0,0,C35/D35) -> 0.0020509833 | L35: ugc_concepts | M35: 50
A36: Mellox Pro message (after the plan allowance) | B36: per message | C36: ='Unit Costs'!$AB$20 -> 0.04822555 | D36: 25 | E36: =D36*Inputs!$B$6 -> 0.25 | F36: =IF(E36=0,"included",1-C36/E36) -> 0.8070978 | G36: =Inputs!$B$33 -> 0.8 | H36: =IF(D36=0,"Included (fair use)",IF(F36>=G36-0.025,"OK","RAISE")) -> OK | I36: =ROUNDUP(C36/(1-G36)/Inputs!$B$6,0) -> 25 | J36: 0.035 | K36: =IF(D36=0,0,C36/D36) -> 0.001929022 | L36: chat_pro | M36: new
A37: Chat with Mellox Flash | B37: per message | C37: ='Unit Costs'!$AB$19 -> 0.0089300575 | D37: 0 | E37: =D37*Inputs!$B$6 -> 0 | F37: =IF(E37=0,"included",1-C37/E37) -> included | G37: =Inputs!$B$33 -> 0.8 | H37: =IF(D37=0,"Included (fair use)",IF(F37>=G37-0.025,"OK","RAISE")) -> Included (fair use) | I37: =ROUNDUP(C37/(1-G37)/Inputs!$B$6,0) -> 5 | J37: 0 | K37: =IF(D37=0,0,C37/D37) -> 0 | L37: chat_flash | M37: 0
A38: Backlink research (10 sites) | B38: per search | C38: ='Unit Costs'!$AB$58 -> 0.030085699 | D38: 0 | E38: =D38*Inputs!$B$6 -> 0 | F38: =IF(E38=0,"included",1-C38/E38) -> included | G38: =Inputs!$B$33 -> 0.8 | H38: =IF(D38=0,"Included (fair use)",IF(F38>=G38-0.025,"OK","RAISE")) -> Included (fair use) | I38: =ROUNDUP(C38/(1-G38)/Inputs!$B$6,0) -> 16 | J38: 0 | K38: =IF(D38=0,0,C38/D38) -> 0 | L38: link_research | M38: 0
A40: Blended COGS per credit (weighted by expected use) | K40: =SUMPRODUCT(J5:J38,K5:K38)/SUM(J5:J38) -> 0.0020341557
A41: Blended margin at face value | K41: =1-K40/Inputs!$B$6 -> 0.79658443
A42: Check: shares sum to | J42: =SUM(J5:J38) -> 1

Sheet Video Credits
A1: Video Credits: a separate allowance so video can never drain the plan
A2: 1 Video Credit (VC) = one 8-second Standard video. KIE runs Veo and Grok for now; OpenRouter runs the rest and is the fallback. Mode is on Inputs.
A4: Option (what the customer sees) | B4: UGC key | C4: Seconds | D4: Resolution | E4: OpenRouter model | F4: OpenRouter cost ($, incl. fee) | G4: KIE model | H4: KIE cost ($) | I4: Cost, active provider ($) | J4: Video credits charged | K4: Cost per VC ($) | L4: Expected share of VC use | M4: Plans that can use it | N4: Provider now (split mode)
A5: Draft (Veo 3.1 Lite) 720p | B5: draft | C5: 8 | D5: 720p | E5: google/veo-3.1-lite | F5: =C5*'Vendor Prices'!$G$17*(1+Inputs!$B$7) -> 0.422 | G5: veo3_lite | H5: ='Vendor Prices'!$G$29 -> 0.15 | I5: =IF(OR(Inputs!$B$30="kie",AND(Inputs!$B$30="split",N5="kie")),(1-Inputs!$B$27)*H5+Inputs!$B$27*F5,F5) -> 0.1636 | J5: 0.5 | K5: =I5/J5 -> 0.3272 | L5: 0.14 | M5: All paid plans | N5: kie
A6: Draft (Veo 3.1 Lite) 1080p | B6: draft | C6: 8 | D6: 1080p | E6: google/veo-3.1-lite | F6: =C6*'Vendor Prices'!$G$18*(1+Inputs!$B$7) -> 0.6752 | G6: veo3_lite | H6: ='Vendor Prices'!$G$30 -> 0.175 | I6: =IF(OR(Inputs!$B$30="kie",AND(Inputs!$B$30="split",N6="kie")),(1-Inputs!$B$27)*H6+Inputs!$B$27*F6,F6) -> 0.20001 | J6: 0.75 | K6: =I6/J6 -> 0.26668 | L6: 0.03 | M6: Growth+ | N6: kie
A7: Standard (Veo 3.1 Fast) 720p | B7: standard | C7: 8 | D7: 720p | E7: google/veo-3.1-fast | F7: =C7*'Vendor Prices'!$G$15*(1+Inputs!$B$7) -> 0.844 | G7: veo3_fast | H7: ='Vendor Prices'!$G$27 -> 0.3 | I7: =IF(OR(Inputs!$B$30="kie",AND(Inputs!$B$30="split",N7="kie")),(1-Inputs!$B$27)*H7+Inputs!$B$27*F7,F7) -> 0.3272 | J7: 1 | K7: =I7/J7 -> 0.3272 | L7: 0.4 | M7: All paid plans | N7: kie
A8: Standard (Veo 3.1 Fast) 1080p | B8: standard | C8: 8 | D8: 1080p | E8: google/veo-3.1-fast | F8: =C8*'Vendor Prices'!$G$16*(1+Inputs!$B$7) -> 1.0128 | G8: veo3_fast | H8: ='Vendor Prices'!$G$28 -> 0.325 | I8: =IF(OR(Inputs!$B$30="kie",AND(Inputs!$B$30="split",N8="kie")),(1-Inputs!$B$27)*H8+Inputs!$B$27*F8,F8) -> 0.35939 | J8: 1.25 | K8: =I8/J8 -> 0.287512 | L8: 0.1 | M8: Growth+ | N8: kie
A9: Premium (Hailuo 3 / Gemini Omni), 8s, 2 photos | B9: premium | C9: 8 | D9: 2K / 1080p | E9: minimax/hailuo-3 | F9: =(C9*'Vendor Prices'!$G$19+2*'Vendor Prices'!$G$20)*(1+Inputs!$B$7) -> 1.1816 | G9: gemini-omni-flash-1-1 | H9: =C9*'Vendor Prices'!$G$35 -> 0.8 | I9: =IF(OR(Inputs!$B$30="kie",AND(Inputs!$B$30="split",N9="kie")),(1-Inputs!$B$27)*H9+Inputs!$B$27*F9,F9) -> 1.1816 | J9: 1.5 | K9: =I9/J9 -> 0.78773333 | L9: 0.1 | M9: Growth+ | N9: openrouter
A10: Premium, 10s, 2 photos | B10: premium | C10: 10 | D10: 2K / 1080p | E10: minimax/hailuo-3 | F10: =(C10*'Vendor Prices'!$G$19+2*'Vendor Prices'!$G$20)*(1+Inputs!$B$7) -> 1.4559 | G10: gemini-omni-flash-1-1 | H10: =C10*'Vendor Prices'!$G$35 -> 1 | I10: =IF(OR(Inputs!$B$30="kie",AND(Inputs!$B$30="split",N10="kie")),(1-Inputs!$B$27)*H10+Inputs!$B$27*F10,F10) -> 1.4559 | J10: 2 | K10: =I10/J10 -> 0.72795 | L10: 0.04 | M10: Growth+ | N10: openrouter
A11: Cinematic (Hailuo 3 / MiniMax H3), 10s | B11: cinematic | C11: 10 | D11: 2K | E11: minimax/hailuo-3 | F11: =(C11*'Vendor Prices'!$G$19+2*'Vendor Prices'!$G$20)*(1+Inputs!$B$7) -> 1.4559 | G11: minimax-h3 | H11: =C11*'Vendor Prices'!$G$36 -> 0.5 | I11: =IF(OR(Inputs!$B$30="kie",AND(Inputs!$B$30="split",N11="kie")),(1-Inputs!$B$27)*H11+Inputs!$B$27*F11,F11) -> 1.4559 | J11: 2 | K11: =I11/J11 -> 0.72795 | L11: 0.04 | M11: Agency+ | N11: openrouter
A12: Long take (Seedance 2.0 Fast), 12s 720p | B12: long | C12: 12 | D12: 720p | E12: bytedance/seedance-2.0-fast | F12: =C12*'Vendor Prices'!$G$22*(1+Inputs!$B$7) -> 1.1485152 | G12: seedance-2-fast | H12: =C12*'Vendor Prices'!$G$32 -> 1.488 | I12: =IF(OR(Inputs!$B$30="kie",AND(Inputs!$B$30="split",N12="kie")),(1-Inputs!$B$27)*H12+Inputs!$B$27*F12,F12) -> 1.1485152 | J12: 1.5 | K12: =I12/J12 -> 0.7656768 | L12: 0.05 | M12: Growth+ | N12: openrouter
A13: Long take, 15s 720p | B13: long | C13: 15 | D13: 720p | E13: bytedance/seedance-2.0-fast | F13: =C13*'Vendor Prices'!$G$22*(1+Inputs!$B$7) -> 1.435644 | G13: seedance-2-fast | H13: =C13*'Vendor Prices'!$G$32 -> 1.86 | I13: =IF(OR(Inputs!$B$30="kie",AND(Inputs!$B$30="split",N13="kie")),(1-Inputs!$B$27)*H13+Inputs!$B$27*F13,F13) -> 1.435644 | J13: 2 | K13: =I13/J13 -> 0.717822 | L13: 0.03 | M13: Growth+ | N13: openrouter
A14: Long take, 15s 480p | B14: long | C14: 15 | D14: 480p | E14: bytedance/seedance-2.0-fast | F14: =C14*'Vendor Prices'!$G$21*(1+Inputs!$B$7) -> 0.63856249 | G14: seedance-2-fast | H14: =C14*'Vendor Prices'!$G$31 -> 0.8775 | I14: =IF(OR(Inputs!$B$30="kie",AND(Inputs!$B$30="split",N14="kie")),(1-Inputs!$B$27)*H14+Inputs!$B$27*F14,F14) -> 0.63856249 | J14: 1 | K14: =I14/J14 -> 0.63856249 | L14: 0.02 | M14: Growth+ | N14: openrouter
A15: Variation (Grok Imagine on KIE), 6s 720p | B15: variation | C15: 6 | D15: 720p | E15: google/veo-3.1-lite (fallback) | F15: =C15*'Vendor Prices'!$G$17*(1+Inputs!$B$7) -> 0.3165 | G15: grok-imagine | H15: ='Vendor Prices'!$G$34 -> 0.12 | I15: =IF(OR(Inputs!$B$30="kie",AND(Inputs!$B$30="split",N15="kie")),(1-Inputs!$B$27)*H15+Inputs!$B$27*F15,F15) -> 0.129825 | J15: 0.5 | K15: =I15/J15 -> 0.25965 | L15: 0.02 | M15: All paid plans | N15: kie
A16: Variation, 6s 480p | B16: variation | C16: 6 | D16: 480p | E16: google/veo-3.1-lite (fallback) | F16: =C16*'Vendor Prices'!$G$17*(1+Inputs!$B$7) -> 0.3165 | G16: grok-imagine | H16: ='Vendor Prices'!$G$33 -> 0.06 | I16: =IF(OR(Inputs!$B$30="kie",AND(Inputs!$B$30="split",N16="kie")),(1-Inputs!$B$27)*H16+Inputs!$B$27*F16,F16) -> 0.072825 | J16: 0.5 | K16: =I16/J16 -> 0.14565 | L16: 0.01 | M16: All paid plans | N16: kie
A17: Studio video 6s (premium key) | B17: premium | C17: 6 | D17: 2K / 1080p | E17: minimax/hailuo-3 | F17: =C17*'Vendor Prices'!$G$19*(1+Inputs!$B$7) -> 0.8229 | G17: gemini-omni-flash-1-1 | H17: =C17*'Vendor Prices'!$G$35 -> 0.6 | I17: =IF(OR(Inputs!$B$30="kie",AND(Inputs!$B$30="split",N17="kie")),(1-Inputs!$B$27)*H17+Inputs!$B$27*F17,F17) -> 0.8229 | J17: 1 | K17: =I17/J17 -> 0.8229 | L17: 0.02 | M17: All paid plans | N17: openrouter
A19: Blended cost per Video Credit (active mode) | K19: =SUMPRODUCT(K5:K17,L5:L17)/SUM(L5:L17) -> 0.44614618
A20: Same on OpenRouter | K20: =SUMPRODUCT(F5:F17/J5:J17,L5:L17)/SUM(L5:L17) -> 0.80883908
A21: Same on KIE | K21: =SUMPRODUCT(H5:H17/J5:J17,L5:L17)/SUM(L5:L17) -> 0.39138333
A22: Check: shares sum to | L22: =SUM(L5:L17) -> 1
A24: Rules that keep video under control
A25: 1. Video spends Video Credits only. General credits can never buy video, so a user cannot burn the whole plan on renders.
A26: 2. Each plan includes a monthly VC allowance; unused VC do not roll over on monthly plans (1 month rollover on annual).
A27: 3. Extra VC come from Video Packs (Add-ons & Packs tab) at a 55-65% margin. Packs never expire.
A28: 4. Hold VC when a render starts, capture on success, release on failure (the UGC reservation already works this way).
A29: 5. Always show the VC price on the Generate button and route 'auto' to Standard unless the brief truly needs Premium.
A30: 6. Keep UGC_MAX_CONCURRENT_RENDERS per plan: Starter 1, Growth 2, Agency 4, Scale 8.

Sheet Add-ons & Packs
A1: Add-ons, credit packs and video packs
A2: Expansion revenue. Every item clears its margin target on its own.
A4: Add-on (monthly) | B4: Price ($) | C4: What's inside | D4: Cost to serve ($) | E4: Margin | F4: Notes
A5: Extra brand (Growth, Agency, Scale) | B5: 39 | C5: 1 workspace, 30 prompts, 1,500 credits, 3 VC, weekly Market Brain, unlimited posts | D5: =30*Plans!$E$36*Inputs!$B$24+1500*Inputs!$B$21*Inputs!$B$37+3*Inputs!$B$22*Inputs!$B$38+150*Inputs!$B$26+Inputs!$B$24*'Unit Costs'!$AB$40+'Unit Costs'!$AB$60+('Unit Costs'!$AB$24+'Unit Costs'!$AB$25+'Unit Costs'!$AB$26)/12+200*'Unit Costs'!$AB$19 -> 9.1639958 | E5: =1-(D5+B5*(Inputs!$B$16+Inputs!$B$18+Inputs!$B$19))/B5 -> 0.69252575
A6: +100 tracked prompts, weekly | B6: 39 | C6: 100 prompts on the plan's engines | D6: =100*Plans!$E$36*Inputs!$B$24 -> 6.8921963 | E6: =1-(D6+B6*(Inputs!$B$16+Inputs!$B$18+Inputs!$B$19))/B6 -> 0.75077702
A7: Daily tracking, per 100 prompts | B7: 149 | C7: Moves 100 prompts from weekly to daily | D7: =100*Plans!$E$36*(Inputs!$B$25-Inputs!$B$24) -> 40.859741 | E7: =1-(D7+B7*(Inputs!$B$16+Inputs!$B$18+Inputs!$B$19))/B7 -> 0.65327355 | F7: 7x the checks
A8: Google AI Overviews engine, per 100 prompts | B8: 15 | C8: Real AI Overview capture via DataForSEO | D8: =100*'Unit Costs'!$AB$52*Inputs!$B$24 -> 0.82739264 | E8: =1-(D8+B8*(Inputs!$B$16+Inputs!$B$18+Inputs!$B$19))/B8 -> 0.87234049 | F8: Closes the Google gap in the probe set
A9: Daily Market Brain, per brand | B9: 29 | C9: Market Brain refresh every day instead of weekly | D9: =(Inputs!$B$25-Inputs!$B$24)*'Unit Costs'!$AB$40 -> 6.2490879 | E9: =1-(D9+B9*(Inputs!$B$16+Inputs!$B$18+Inputs!$B$19))/B9 -> 0.71201421 | F9: Opus refresh costs $0.25
A10: +200 Mellox Pro messages | B10: 29 | C10: Extra Claude Opus 5.5 chat | D10: =200*0.8*'Unit Costs'!$AB$20 -> 7.716088 | E10: =1-(D10+B10*(Inputs!$B$16+Inputs!$B$18+Inputs!$B$19))/B10 -> 0.661428 | F10: Assumes 80% of a bought pack is used
A11: Extra seat (Starter, Growth) | B11: 15 | C11: One more teammate | D11: =100*'Unit Costs'!$AB$19 -> 0.89300575 | E11: =1-(D11+B11*(Inputs!$B$16+Inputs!$B$18+Inputs!$B$19))/B11 -> 0.86796628
A12: White-label domain (Agency, Scale) | B12: 49 | C12: Client portal on the agency's domain | D12: =2 -> 2 | E12: =1-(D12+B12*(Inputs!$B$16+Inputs!$B$18+Inputs!$B$19))/B12 -> 0.88668367
A14: Credit pack (never expires) | B14: Price ($) | C14: Bonus (AI only) | D14: Credits | E14: Fees ($) | F14: COGS if fully used ($) | G14: Margin
A15: $25 credit pack | B15: 25 | C15: 0 | D15: =B15/Inputs!$B$6*(1+C15) -> 2500 | E15: =B15*(Inputs!$B$16+Inputs!$B$18+Inputs!$B$19)+Inputs!$B$17 -> 2.3125 | F15: =D15*Inputs!$B$37 -> 5.0853891 | G15: =(B15-E15-F15)/B15 -> 0.70408443
A16: $100 credit pack | B16: 100 | C16: 0.05 | D16: =B16/Inputs!$B$6*(1+C16) -> 10500 | E16: =B16*(Inputs!$B$16+Inputs!$B$18+Inputs!$B$19)+Inputs!$B$17 -> 7.75 | F16: =D16*Inputs!$B$37 -> 21.358634 | G16: =(B16-E16-F16)/B16 -> 0.70891366
A17: $250 credit pack | B17: 250 | C17: 0.1 | D17: =B17/Inputs!$B$6*(1+C17) -> 27500 | E17: =B17*(Inputs!$B$16+Inputs!$B$18+Inputs!$B$19)+Inputs!$B$17 -> 18.625 | F17: =D17*Inputs!$B$37 -> 55.939281 | G17: =(B17-E17-F17)/B17 -> 0.70174288
A18: $500 credit pack | B18: 500 | C18: 0.15 | D18: =B18/Inputs!$B$6*(1+C18) -> 57500 | E18: =B18*(Inputs!$B$16+Inputs!$B$18+Inputs!$B$19)+Inputs!$B$17 -> 36.75 | F18: =D18*Inputs!$B$37 -> 116.96395 | G18: =(B18-E18-F18)/B18 -> 0.6925721
A20: Video pack (never expires) | B20: Price ($) | C20: Video credits | D20: Price per VC ($) | E20: Fees ($) | F20: COGS, active provider ($) | G20: Margin | H20: COGS on KIE ($) | I20: Margin if KIE
A21: 10 video credits | B21: 29 | C21: 10 | D21: =B21/C21 -> 2.9 | E21: =B21*(Inputs!$B$16+Inputs!$B$18+Inputs!$B$19)+Inputs!$B$17 -> 2.6025 | F21: =C21*Inputs!$B$38 -> 4.4614618 | G21: =(B21-E21-F21)/B21 -> 0.75641511 | H21: =C21*'Video Credits'!$K$21 -> 3.9138333 | I21: =(B21-E21-H21)/B21 -> 0.77529885
A22: 30 video credits | B22: 79 | C22: 30 | D22: =B22/C22 -> 2.6333333 | E22: =B22*(Inputs!$B$16+Inputs!$B$18+Inputs!$B$19)+Inputs!$B$17 -> 6.2275 | F22: =C22*Inputs!$B$38 -> 13.384385 | G22: =(B22-E22-F22)/B22 -> 0.75174828 | H22: =C22*'Video Credits'!$K$21 -> 11.7415 | I22: =(B22-E22-H22)/B22 -> 0.7725443
A23: 100 video credits | B23: 249 | C23: 100 | D23: =B23/C23 -> 2.49 | E23: =B23*(Inputs!$B$16+Inputs!$B$18+Inputs!$B$19)+Inputs!$B$17 -> 18.5525 | F23: =C23*Inputs!$B$38 -> 44.614618 | G23: =(B23-E23-F23)/B23 -> 0.74631679 | H23: =C23*'Video Credits'!$K$21 -> 39.138333 | I23: =(B23-E23-H23)/B23 -> 0.76830991
A25: Average margin on packs (used for top-up revenue in the projection) | G25: =AVERAGE(G15:G18,G21:G23) -> 0.72311332

Sheet Retention & Growth
A1: Retention and growth: what keeps customers paying and upgrading
A2: Levers are built into the plans; the table below turns churn and CAC assumptions into LTV and payback.
A4: Lever | B4: How it works | C4: Cost to Mellox | D4: Expected effect (assumption) | E4: Where it lives
A5: Weekly auto Coach briefing | B5: A Monday email and in-app briefing per brand: what changed, what to post, what to fix | C5: ~$0.87 per brand per month | D5: Biggest habit driver; brings users back weekly | E5: Plans: coach_auto; coach.briefing
A6: Weekly AI-visibility report | B6: Email showing prompt wins/losses and competitor citations | C6: Included in prompt tracking | D6: Shows value even in quiet weeks | E6: geo scans + probes
A7: Separate video allowance | B7: Video never drains the credits people use for posts and articles | C7: None (protects margin) | D7: Fewer 'I ran out on day 3' cancellations | E7: Video Credits tab
A8: Rollover on annual plans | B8: Unused credits and VC roll over up to one month | C8: Small (less breakage) | D8: Pushes annual billing; lowers churn | E8: Credit ledger: expire job
A9: Pause instead of cancel | B9: $9/month keeps data, brands and 10 weekly prompts | C9: ~$1 per month | D9: Saves an estimated 20-30% of would-be cancellations | E9: Billing flow
A10: 80% usage nudges | B10: In-app + email at 80% of credits, VC or Pro messages with 1-click packs or upgrade | C10: None | D10: Converts heavy users to packs or the next plan | E10: budget.ts warn state
A11: Founding-customer offer | B11: First 50 paying customers: 30% off for 12 months, annual | C11: Discount only | D11: Early logos, case studies, cash upfront | E11: Paddle coupon
A12: Referral credits | B12: Both sides get 1,000 credits + 2 VC | C12: ~$3.80 per referral | D12: Cheapest acquisition channel for SMBs | E12: Credit ledger: grant
A13: Agency partner program | B13: 20% recurring commission for 12 months to agencies and consultants who resell | C13: 20% of revenue | D13: Channel into the agency segment | E13: Paddle affiliates
A14: 14-day Growth trial (card required) | B14: 500 credits, 2 VC, 20 Pro messages, 3 brands | C14: Up to ~$5 per trial | D14: Higher conversion than an open free tier | E14: Plans + Paddle trial
A15: Free plan as a lead magnet | B15: 5 prompts, 1 scan, 30 messages, 100 one-time credits | C15: ~$0.95 / month + $0.34 onboarding | D15: Top of funnel; upgrade when competitors show up in answers | E15: Plans: Free
A17: Unit economics per customer | B17: Starter | C17: Growth | D17: Agency | E17: Scale | F17: Notes
A18: Subscription revenue after annual discounts | B18: =Plans!$D$6*(1-Inputs!$B$32*Inputs!$B$31) -> 46.54951 | C18: =Plans!$E$6*(1-Inputs!$B$32*Inputs!$B$31) -> 141.54851 | D18: =Plans!$F$6*(1-Inputs!$B$32*Inputs!$B$31) -> 426.54551 | E18: =Plans!$G$6*(1-Inputs!$B$32*Inputs!$B$31) -> 1139.038
A19: Expansion revenue (add-ons, packs) as % of subscription | B19: 0.05 | C19: 0.12 | D19: 0.2 | E19: 0.15
A20: ARPA per month | B20: =B18*(1+B19) -> 48.876986 | C20: =C18*(1+C19) -> 158.53433 | D20: =D18*(1+D19) -> 511.85461 | E20: =E18*(1+E19) -> 1309.8937
A21: Cost to serve (typical) + fees | B21: =Plans!$D$54+B20*(Inputs!$B$16+Inputs!$B$18+Inputs!$B$19)+Inputs!$B$17+B18*B19*0.35 -> 16.786206 | C21: =Plans!$E$54+C20*(Inputs!$B$16+Inputs!$B$18+Inputs!$B$19)+Inputs!$B$17+C18*C19*0.35 -> 55.404767 | D21: =Plans!$F$54+D20*(Inputs!$B$16+Inputs!$B$18+Inputs!$B$19)+Inputs!$B$17+D18*D19*0.35 -> 183.4105 | E21: =Plans!$G$54+E20*(Inputs!$B$16+Inputs!$B$18+Inputs!$B$19)+Inputs!$B$17+E18*E19*0.35 -> 506.81376 | F21: Expansion revenue carries ~35% cost
A22: Contribution per month | B22: =B20-B21 -> 32.09078 | C22: =C20-C21 -> 103.12956 | D22: =D20-D21 -> 328.44412 | E22: =E20-E21 -> 803.07995
A23: Monthly churn without the levers | B23: 0.07 | C23: 0.05 | D23: 0.04 | E23: 0.025
A24: Churn reduction from the levers (points) | B24: 0.015 | C24: 0.012 | D24: 0.01 | E24: 0.005
A25: Monthly churn with the levers | B25: =MAX(0.005,B23-B24) -> 0.055 | C25: =MAX(0.005,C23-C24) -> 0.038 | D25: =MAX(0.005,D23-D24) -> 0.03 | E25: =MAX(0.005,E23-E24) -> 0.02
A26: Average lifetime without levers (months) | B26: =1/B23 -> 14.285714 | C26: =1/C23 -> 20 | D26: =1/D23 -> 25 | E26: =1/E23 -> 40
A27: Average lifetime with levers (months) | B27: =1/B25 -> 18.181818 | C27: =1/C25 -> 26.315789 | D27: =1/D25 -> 33.333333 | E27: =1/E25 -> 50
A28: Lifetime contribution (LTV) without levers | B28: =B22*B26 -> 458.43971 | C28: =C22*C26 -> 2062.5913 | D28: =D22*D26 -> 8211.1029 | E28: =E22*E26 -> 32123.198
A29: Lifetime contribution (LTV) with levers | B29: =B22*B27 -> 583.46872 | C29: =C22*C27 -> 2713.9359 | D29: =D22*D27 -> 10948.137 | E29: =E22*E27 -> 40153.998
A30: Acquisition cost (CAC) | B30: 60 | C30: 150 | D30: 450 | E30: 1500 | F30: Agency and Scale need founder-led sales
A31: CAC payback (months) | B31: =B30/B22 -> 1.8696959 | C31: =C30/C22 -> 1.4544811 | D31: =D30/D22 -> 1.3700961 | E31: =E30/E22 -> 1.867809
A32: LTV : CAC (with levers) | B32: =B29/B30 -> 9.7244787 | C32: =C29/C30 -> 18.092906 | D32: =D29/D30 -> 24.329194 | E32: =E29/E30 -> 26.769332 | F32: Healthy SaaS is 3x or more

Sheet Unit Costs
A1: Cost of every AI task on the new model stack (USD, expected case)
A2: Tier column uses PREMIUM / WORKHORSE / ECONOMY from Inputs, or a model key. Reasoning tokens come from the Inputs table unless overridden. Includes 3% fallback traffic and the 5.5% OpenRouter fee.
A4: ID | B4: Area | C4: Action | D4: Route label (task-models.ts) | E4: Tier / model | F4: Effort | G4: Input tokens / call | H4: Answer tokens / call | I4: Calls per action | J4: Cached input share | K4: Reasoning override | L4: Tavily credits | M4: Other cost key | N4: Other qty | O4: Fixed adder ($) | P4: Model resolved | Q4: Reasoning tokens | R4: In $/1M | S4: Out $/1M | T4: Cache $/1M | U4: Token factor | V4: Primary LLM ($) | W4: Fallback model | X4: Fallback LLM ($) | Y4: LLM blended ($) | Z4: Search ($) | AA4: Other ($) | AB4: Expected COGS ($) | AC4: Worst multiplier | AD4: Worst COGS ($) | AE4: Assumptions
A5: c_naturalize | B5: Component | C5: Caption naturalize pass | D5: studio.naturalize | E5: WORKHORSE | F5: low | G5: 1500 | H5: 500 | I5: 1 | J5: 0 | L5: 0 | P5: =IF(E5="PREMIUM",Inputs!$B$9,IF(E5="WORKHORSE",Inputs!$B$10,IF(E5="ECONOMY",Inputs!$B$11,E5))) -> google/gemini-3.8-flash | Q5: =IF(K5<>"",K5,IF(F5="",0,IFERROR(INDEX(Inputs!$B$42:$D$44,MATCH(E5,Inputs!$A$42:$A$44,0),IF(F5="low",1,IF(F5="medium",2,3))),0))) -> 500 | R5: =IF(P5="",0,INDEX('Vendor Prices'!$G$5:$G$58,MATCH(P5,'Vendor Prices'!$A$5:$A$58,0))) -> 0.75 | S5: =IF(P5="",0,INDEX('Vendor Prices'!$H$5:$H$58,MATCH(P5,'Vendor Prices'!$A$5:$A$58,0))) -> 3.75 | T5: =IF(P5="",0,IF(INDEX('Vendor Prices'!$I$5:$I$58,MATCH(P5,'Vendor Prices'!$A$5:$A$58,0))=0,R5,INDEX('Vendor Prices'!$I$5:$I$58,MATCH(P5,'Vendor Prices'!$A$5:$A$58,0)))) -> 0.1875 | U5: =IF(LEFT(P5,10)="anthropic/",Inputs!$B$8,1) -> 1 | V5: =IF(P5="",0,I5*(G5*U5*((1-J5)*R5+J5*T5)+(H5+Q5)*U5*S5)/1000000*(1+Inputs!$B$7)) -> 0.005143125 | W5: =IF(E5="PREMIUM",Inputs!$B$12,IF(E5="WORKHORSE",Inputs!$B$13,IF(E5="ECONOMY",Inputs!$B$14,""))) -> openai/gpt-5.6-terra | X5: =IF(W5="",V5,I5*(G5*((1-J5)*INDEX('Vendor Prices'!$G$5:$G$58,MATCH(W5,'Vendor Prices'!$A$5:$A$58,0))+J5*INDEX('Vendor Prices'!$I$5:$I$58,MATCH(W5,'Vendor Prices'!$A$5:$A$58,0)))+(H5+Q5)*INDEX('Vendor Prices'!$H$5:$H$58,MATCH(W5,'Vendor Prices'!$A$5:$A$58,0)))/1000000*(1+Inputs!$B$7)) -> 0.015825 | Y5: =(1-Inputs!$B$15)*V5+Inputs!$B$15*X5 -> 0.0054635813 | Z5: =L5*Inputs!$B$29 -> 0 | AA5: =IF(M5="",0,N5*INDEX('Vendor Prices'!$G$5:$G$58,MATCH(M5,'Vendor Prices'!$A$5:$A$58,0))*(1+INDEX('Vendor Prices'!$J$5:$J$58,MATCH(M5,'Vendor Prices'!$A$5:$A$58,0))*Inputs!$B$7)) -> 0 | AB5: =Y5+Z5+AA5+O5 -> 0.0054635813 | AC5: 1.5 | AD5: =AB5*AC5 -> 0.0081953719 | AE5: Runs on ~30% of caption jobs
A6: c_summary | B6: Component | C6: Chat history summary | D6: chat.history-summary | E6: ECONOMY | F6: low | G6: 6000 | H6: 600 | I6: 1 | J6: 0 | L6: 0 | P6: =IF(E6="PREMIUM",Inputs!$B$9,IF(E6="WORKHORSE",Inputs!$B$10,IF(E6="ECONOMY",Inputs!$B$11,E6))) -> google/gemini-3.1-flash-lite | Q6: =IF(K6<>"",K6,IF(F6="",0,IFERROR(INDEX(Inputs!$B$42:$D$44,MATCH(E6,Inputs!$A$42:$A$44,0),IF(F6="low",1,IF(F6="medium",2,3))),0))) -> 200 | R6: =IF(P6="",0,INDEX('Vendor Prices'!$G$5:$G$58,MATCH(P6,'Vendor Prices'!$A$5:$A$58,0))) -> 0.25 | S6: =IF(P6="",0,INDEX('Vendor Prices'!$H$5:$H$58,MATCH(P6,'Vendor Prices'!$A$5:$A$58,0))) -> 1.5 | T6: =IF(P6="",0,IF(INDEX('Vendor Prices'!$I$5:$I$58,MATCH(P6,'Vendor Prices'!$A$5:$A$58,0))=0,R6,INDEX('Vendor Prices'!$I$5:$I$58,MATCH(P6,'Vendor Prices'!$A$5:$A$58,0)))) -> 0.0625 | U6: =IF(LEFT(P6,10)="anthropic/",Inputs!$B$8,1) -> 1 | V6: =IF(P6="",0,I6*(G6*U6*((1-J6)*R6+J6*T6)+(H6+Q6)*U6*S6)/1000000*(1+Inputs!$B$7)) -> 0.0028485 | W6: =IF(E6="PREMIUM",Inputs!$B$12,IF(E6="WORKHORSE",Inputs!$B$13,IF(E6="ECONOMY",Inputs!$B$14,""))) -> openai/gpt-5.6-luna | X6: =IF(W6="",V6,I6*(G6*((1-J6)*INDEX('Vendor Prices'!$G$5:$G$58,MATCH(W6,'Vendor Prices'!$A$5:$A$58,0))+J6*INDEX('Vendor Prices'!$I$5:$I$58,MATCH(W6,'Vendor Prices'!$A$5:$A$58,0)))+(H6+Q6)*INDEX('Vendor Prices'!$H$5:$H$58,MATCH(W6,'Vendor Prices'!$A$5:$A$58,0)))/1000000*(1+Inputs!$B$7)) -> 0.0022788 | Y6: =(1-Inputs!$B$15)*V6+Inputs!$B$15*X6 -> 0.002831409 | Z6: =L6*Inputs!$B$29 -> 0 | AA6: =IF(M6="",0,N6*INDEX('Vendor Prices'!$G$5:$G$58,MATCH(M6,'Vendor Prices'!$A$5:$A$58,0))*(1+INDEX('Vendor Prices'!$J$5:$J$58,MATCH(M6,'Vendor Prices'!$A$5:$A$58,0))*Inputs!$B$7)) -> 0 | AB6: =Y6+Z6+AA6+O6 -> 0.002831409 | AC6: 1.5 | AD6: =AB6*AC6 -> 0.0042471135 | AE6: Every 8 turns
A7: c_moderation | B7: Component | C7: Image moderation | D7: guardrails.image-moderation | E7: ECONOMY | F7: low | G7: 1500 | H7: 100 | I7: 1 | J7: 0 | L7: 0 | P7: =IF(E7="PREMIUM",Inputs!$B$9,IF(E7="WORKHORSE",Inputs!$B$10,IF(E7="ECONOMY",Inputs!$B$11,E7))) -> google/gemini-3.1-flash-lite | Q7: =IF(K7<>"",K7,IF(F7="",0,IFERROR(INDEX(Inputs!$B$42:$D$44,MATCH(E7,Inputs!$A$42:$A$44,0),IF(F7="low",1,IF(F7="medium",2,3))),0))) -> 200 | R7: =IF(P7="",0,INDEX('Vendor Prices'!$G$5:$G$58,MATCH(P7,'Vendor Prices'!$A$5:$A$58,0))) -> 0.25 | S7: =IF(P7="",0,INDEX('Vendor Prices'!$H$5:$H$58,MATCH(P7,'Vendor Prices'!$A$5:$A$58,0))) -> 1.5 | T7: =IF(P7="",0,IF(INDEX('Vendor Prices'!$I$5:$I$58,MATCH(P7,'Vendor Prices'!$A$5:$A$58,0))=0,R7,INDEX('Vendor Prices'!$I$5:$I$58,MATCH(P7,'Vendor Prices'!$A$5:$A$58,0)))) -> 0.0625 | U7: =IF(LEFT(P7,10)="anthropic/",Inputs!$B$8,1) -> 1 | V7: =IF(P7="",0,I7*(G7*U7*((1-J7)*R7+J7*T7)+(H7+Q7)*U7*S7)/1000000*(1+Inputs!$B$7)) -> 0.000870375 | W7: =IF(E7="PREMIUM",Inputs!$B$12,IF(E7="WORKHORSE",Inputs!$B$13,IF(E7="ECONOMY",Inputs!$B$14,""))) -> openai/gpt-5.6-luna | X7: =IF(W7="",V7,I7*(G7*((1-J7)*INDEX('Vendor Prices'!$G$5:$G$58,MATCH(W7,'Vendor Prices'!$A$5:$A$58,0))+J7*INDEX('Vendor Prices'!$I$5:$I$58,MATCH(W7,'Vendor Prices'!$A$5:$A$58,0)))+(H7+Q7)*INDEX('Vendor Prices'!$H$5:$H$58,MATCH(W7,'Vendor Prices'!$A$5:$A$58,0)))/1000000*(1+Inputs!$B$7)) -> 0.0006963 | Y7: =(1-Inputs!$B$15)*V7+Inputs!$B$15*X7 -> 0.00086515275 | Z7: =L7*Inputs!$B$29 -> 0 | AA7: =IF(M7="",0,N7*INDEX('Vendor Prices'!$G$5:$G$58,MATCH(M7,'Vendor Prices'!$A$5:$A$58,0))*(1+INDEX('Vendor Prices'!$J$5:$J$58,MATCH(M7,'Vendor Prices'!$A$5:$A$58,0))*Inputs!$B$7)) -> 0 | AB7: =Y7+Z7+AA7+O7 -> 0.00086515275 | AC7: 1.5 | AD7: =AB7*AC7 -> 0.0012977291
A8: c_file_escal | B8: Component | C8: File extract escalation | D8: file-extract (escalated) | E8: WORKHORSE | F8: low | G8: 8000 | H8: 1500 | I8: 1 | J8: 0 | L8: 0 | P8: =IF(E8="PREMIUM",Inputs!$B$9,IF(E8="WORKHORSE",Inputs!$B$10,IF(E8="ECONOMY",Inputs!$B$11,E8))) -> google/gemini-3.8-flash | Q8: =IF(K8<>"",K8,IF(F8="",0,IFERROR(INDEX(Inputs!$B$42:$D$44,MATCH(E8,Inputs!$A$42:$A$44,0),IF(F8="low",1,IF(F8="medium",2,3))),0))) -> 500 | R8: =IF(P8="",0,INDEX('Vendor Prices'!$G$5:$G$58,MATCH(P8,'Vendor Prices'!$A$5:$A$58,0))) -> 0.75 | S8: =IF(P8="",0,INDEX('Vendor Prices'!$H$5:$H$58,MATCH(P8,'Vendor Prices'!$A$5:$A$58,0))) -> 3.75 | T8: =IF(P8="",0,IF(INDEX('Vendor Prices'!$I$5:$I$58,MATCH(P8,'Vendor Prices'!$A$5:$A$58,0))=0,R8,INDEX('Vendor Prices'!$I$5:$I$58,MATCH(P8,'Vendor Prices'!$A$5:$A$58,0)))) -> 0.1875 | U8: =IF(LEFT(P8,10)="anthropic/",Inputs!$B$8,1) -> 1 | V8: =IF(P8="",0,I8*(G8*U8*((1-J8)*R8+J8*T8)+(H8+Q8)*U8*S8)/1000000*(1+Inputs!$B$7)) -> 0.0142425 | W8: =IF(E8="PREMIUM",Inputs!$B$12,IF(E8="WORKHORSE",Inputs!$B$13,IF(E8="ECONOMY",Inputs!$B$14,""))) -> openai/gpt-5.6-terra | X8: =IF(W8="",V8,I8*(G8*((1-J8)*INDEX('Vendor Prices'!$G$5:$G$58,MATCH(W8,'Vendor Prices'!$A$5:$A$58,0))+J8*INDEX('Vendor Prices'!$I$5:$I$58,MATCH(W8,'Vendor Prices'!$A$5:$A$58,0)))+(H8+Q8)*INDEX('Vendor Prices'!$H$5:$H$58,MATCH(W8,'Vendor Prices'!$A$5:$A$58,0)))/1000000*(1+Inputs!$B$7)) -> 0.0422 | Y8: =(1-Inputs!$B$15)*V8+Inputs!$B$15*X8 -> 0.015081225 | Z8: =L8*Inputs!$B$29 -> 0 | AA8: =IF(M8="",0,N8*INDEX('Vendor Prices'!$G$5:$G$58,MATCH(M8,'Vendor Prices'!$A$5:$A$58,0))*(1+INDEX('Vendor Prices'!$J$5:$J$58,MATCH(M8,'Vendor Prices'!$A$5:$A$58,0))*Inputs!$B$7)) -> 0 | AB8: =Y8+Z8+AA8+O8 -> 0.015081225 | AC8: 1.5 | AD8: =AB8*AC8 -> 0.022621837 | AE8: ~20% of reads are thin and escalate
